---
layout: single
published: true
title: "반복문-12단계_A+B - 4 "
categories: coding_test
tag: [python, beakjoon_bronze, while문, try, except, EOF]
toc: true
author_profile: false
sidebar:
    nav: "docs"
---

<br>

| 단계  | 제목      | 설명                                       |         |
| --- | ------- | ---------------------------------------- | ------- |
| 3   | 반복문     | for, while 등의 반복문을 사용해 봅시다.              |         |
|     | **소단계** | **문제번호**                                 | **제목**  |
|     | 12      | 10951                                    | A+B - 4 |
|     |         | 입력이 끝날 때까지 A+B를 출력하는 문제. EOF에 대해 알아 보세요. |         |

## 문제

두 정수 A와 B를 입력받은 다음, A+B를 출력하는 프로그램을 작성하시오.

## 입력

입력은 여러 개의 테스트 케이스로 이루어져 있다.

각 테스트 케이스는 한 줄로 이루어져 있으며, 각 줄에 A와 B가 주어진다. (0 < A, B < 10)

## 출력

각 테스트 케이스마다 A+B를 출력한다.

## 내 제출

```python
미제출
```

## 결과

## 수정 제출

```python
while True:
    try:
        a, b = map(int, input().split())
        print(a+b)

    except EOFError:
        break
```

## 결과

정답

## 오답 이유

이번문제는 try except 를 사용하여 try 과정에서 입력을 무한 지속해주고, 입력이 없을때 의 에러인 E0FError 를 except 조건으로 만들어 주어, 코드의 에러상황이 발생(입력없음) 시 except 로 빠져나가 break 하게 해줍니다.

## 사용된 코드 이론

<br>

 예외(exception)란 코드를 실행하는 중에 발생한 에러를 뜻합니다. 다음과 같이 10을 어떤 값으로 나누는 함수 ten_div가 있을 때 인수에 따라 정상으로 동작하기도 하고 에러가 나기도 합니다.

```python
>>> def ten_div(x):
...     return 10 / x
...
```

이 함수에 2를 넣으면 5.0이 나옵니다.

```python
>>> ten_div(2)
5.0
```

하지만 0을 넣으면 실행하는 중에 에러가 발생합니다. 이런 상황을 예외라고 하는데 여기서는 어떤 숫자를 0으로 나누어서 ZeroDivisionError 예외가 발생했습니다.

```python
>>> ten_div(0)
Traceback (most recent call last):
  File "<pyshell#121>", line 1, in <module>
    ten_div(0)
  File "<pyshell#119>", line 2, in ten_div
    return 10 / x
ZeroDivisionError: division by zero 
```

ZeroDivisionError뿐만 아니라 지금까지 만난 AttributeError, NameError, TypeError 등 다양한 에러들도 모두 예외입니다.

이번에는 예외가 발생했을 때도 스크립트 실행을 중단하지 않고 계속 실행하게 해주는 예외 처리 방법에 대해 알아보겠습니다.

## 38.1 try except로 사용하기

예외 처리를 하려면 다음과 같이 try에 실행할 코드를 넣고 except에 예외가 발생했을 때 처리하는 코드를 넣습니다.

```python
try:
    실행할 코드
except:
    예외가 발생했을 때 처리하는 코드
```

이제 숫자를 0으로 나누었을 때 발생하는 예외를 처리해보겠습니다.

```python
try:
    x = int(input('나눌 숫자를 입력하세요: '))
    y = 10 / x
    print(y)
except:    # 예외가 발생했을 때 실행됨
    print('예외가 발생했습니다.')
```

소스 코드를 실행한 뒤 **0**을 입력하고 엔터 키를 누르세요.

실행 결과

```python
나눌 숫자를 입력하세요: 0 (입력)
예외가 발생했습니다.
```

숫자를 0으로 나누면 ZeroDivisionError 예외가 발생합니다. 여기서는 except에서 예외 처리를 하도록 만들었으므로 '예외가 발생했습니다.'가 출력됩니다.

특히 예외가 발생하면 해당 줄에서 코드 실행을 중단하고 바로 except로 가서 코드를 실행합니다. 즉, try의 y = 10 / x를 비롯하여 그 아래줄에 있는 print(y)도 실행되지 않습니다.

▼ **그림 38-1** 예외 발생과 except

![](https://dojang.io/pluginfile.php/13945/mod_page/content/2/038001.png)

다시 소스 코드를 실행한 뒤 **2**를 입력하고 엔터 키를 누르세요.

```python
나눌 숫자를 입력하세요: 2 (입력)
5.0
```

2를 입력하니 예외가 발생하지 않고 계산 결과가 잘 출력됩니다. 이처럼 try의 코드가 에러 없이 잘 실행 되면 except의 코드는 실행되지 않고 그냥 넘어갑니다. 즉, try의 코드에서 에러가 발생했을 때만 except의 코드가 실행됩니다.

### 38.1.1  특정 예외만 처리하기

이번에는 except에 예외 이름을 지정해서 특정 예외가 발생했을 때만 처리 코드를 실행하도록 만들어보겠습니다.

```python
try:
    실행할 코드
except 예외이름:
    예외가 발생했을 때 처리하는 코드
```

다음과 같이 정수 두 개를 입력받아서 하나는 리스트의 인덱스로 사용하고, 하나는 나누는 값으로 사용합니다. 그리고 except를 두 개 사용하고 각각 ZeroDivisionError와 IndexError를 지정합니다.

```python
y = [10, 20, 30]

try:
    index, x = map(int, input('인덱스와 나눌 숫자를 입력하세요: ').split())
    print(y[index] / x)
except ZeroDivisionError:    # 숫자를 0으로 나눠서 에러가 발생했을 때 실행됨
    print('숫자를 0으로 나눌 수 없습니다.')
except IndexError:           # 범위를 벗어난 인덱스에 접근하여 에러가 발생했을 때 실행됨
    print('잘못된 인덱스입니다.')
```

소스 코드를 실행한 뒤 **2 0**을 입력하고 엔터 키를 누르세요.

```python
인덱스와 나눌 숫자를 입력하세요: 2 0 (입력)
숫자를 0으로 나눌 수 없습니다.
```

2 0을 입력하면 10 / 0이 되므로 숫자를 0으로 나누게 됩니다. 이때는 except ZeroDivisionError:의 처리 코드가 실행됩니다.

다시 소스 코드를 실행한 뒤 **3 5**를 입력하고 엔터 키를 누릅니다.

```python
인덱스와 나눌 숫자를 입력하세요: 3 5 (입력)
잘못된 인덱스입니다.
```

y = [10, 20, 30]은 요소가 3개 들어있는 리스트입니다. 따라서 인덱스에 3을 지정하면 범위를 벗어나게 됩니다. 이때는 except IndexError:의 처리 코드가 실행됩니다.

### 38.1.2  예외의 에러 메시지 받아오기

특히 except에서 as 뒤에 변수를 지정하면 발생한 예외의 에러 메시지를 받아올 수 있습니다.

```python
try:
    실행할 코드
except 예외 as 변수:
    예외가 발생했을 때 처리하는 코드
```

앞에서 만든 코드의 except에 as e를 넣습니다. 보통 예외( **e**xception)의 e를 따서 변수 이름을 e로 짓습니다.

```python
y = [10, 20, 30]

try:
    index, x = map(int, input('인덱스와 나눌 숫자를 입력하세요: ').split())
    print(y[index] / x)
except ZeroDivisionError as e:                    # as 뒤에 변수를 지정하면 에러를 받아옴
    print('숫자를 0으로 나눌 수 없습니다.', e)    # e에 저장된 에러 메시지 출력
except IndexError as e:
    print('잘못된 인덱스입니다.', e)
```

실행 결과

```python
인덱스와 나눌 숫자를 입력하세요: 2 0 (입력)
숫자를 0으로 나눌 수 없습니다. division by zero
```

실행 결과

```python
인덱스와 나눌 숫자를 입력하세요: 3 5 (입력)
잘못된 인덱스입니다. list index out of range
```

2 0, 3 5처럼 예외가 발생하는 숫자를 넣어보면 해당 예외에 해당하는 에러 메시지가 출력됩니다. 단, 예외가 여러 개 발생하더라도 먼저 발생한 예외의 처리 코드만 실행됩니다(또는, 예외 중에서 높은 계층의 예외부터 처리됩니다. 기반 클래스 > 파생 클래스 순).

참고로 모든 예외의 에러 메시지를 출력하고 싶다면 다음과 같이 except에 Exception을 지정하고 as 뒤에 변수를 넣으면 됩니다.

```python
except Exception as e:    # 모든 예외의 에러 메시지를 출력할 때는 Exception을 사용
    print('예외가 발생했습니다.', e)
```

이처럼 예외 처리는 에러가 발생하더라도 스크립트의 실행을 중단시키지 않고 계속 실행하고자 할 때 사용합니다.

```
참고 | 예외 계층

예외도 클래스 상속으로 구현되며 다음과 같은 계층으로 이루어져 있습니다. 보통 파이썬에서 새로운 예외를 만들 때는 Exception을 상속받아서 구현합니다.

전체 계층도는 파이썬 공식 문서를 참조하세요.
```

Built-in Exceptions: https://docs.python.org/3/library/exceptions.html#exception-hierarchy

▼ **그림 38-2** 파이썬 예외 계층도

![](https://dojang.io/pluginfile.php/13945/mod_page/content/2/038002.png)

---

---

## 참고문헌

[파이썬 코딩 도장: 38.1 try except로 사용하기](https://dojang.io/mod/page/view.php?id=2398)
